Workbook

Sheet Montage
A1: Roboterauslieferungsliste 01.26
A2: Kunde:
A3: Anschrift:
A4: LC Wernberg
A5: Kundennr:
A6: Projektnr: | D6: Telefon:
A7: Seriennr: | D7: Lieferdatum:
A8: Auftragsnr: | D8: Projektierer:
A9: Artikelnr.: | B9: Lagerort: | C9: Artikel: | D9: Stück | E9: Länge (m) | F9: Ausge liefert | G9: Nachlie ferung
A10: L9118500995 | B10: R04R02C3 | C10: Milchleitung (100m) | E10: ---
A11: FE844746 | B11: R03R01F2 | C11: Stromkabel, abgeschirmt 3x 2,5 ² | E11: ---
A12: L9106501260 | B12: R04R01C3 | C12: Schlauch grün 19mm | E12: ---
A13: L9106501000 | B13: R04R02C2 | C13: Schlauch rot 19mm | E13: ---
A14: L9106501270 | B14: R04R01C1 | C14: Schlauch blau 19mm | E14: ---
A15: L9118501603 | B15: R04R02C1 | C15: Vakuumschlauch (30m) | E15: ---
A16: L9118501006 | B16: R04R04B1 | C16: Isolierung normal (2m/Stück) | D16: ---
A17: LD221420101935 | B17: *10 | C17: Isol. groß 35 mm (1m/Stück) | D17: ---
A18: FE224457 | B18: WALA01 | C18: Gitterrinne 60x100 (3m) | D18: ---
A19: FE224632 | B19: WALA01 | C19: Gitterrinne 60x300 (3m) | D19: ---
A20: FE224633 | B20: WALA01 | C20: Gitterrinne 60x400 (3m) | D20: ---
A21: FE045973 | B21: R02R02F1 | C21: Ausleger für Gitterr.(100mm) pro mtr./1 Stk. | D21: ---
A22: FE045975 | B22: R02R02F2 | C22: Ausleger für Gitterr. (300mm) pro mtr./1 Stk. | D22: ---
A23: FE045976 | B23: R04R01B1 | C23: Ausleger für Gitterr. (400mm) pro mtr./1 Stk. | D23: 2
A24: FE045978 | B24: *10 | C24: Ausleger für Gitterr. (600mm) pro mtr./1 Stk. | D24: ---
A25: QU2641540 | B25: *10 | C25: Ausleger für Gitterr. (800mm) pro mtr./1 Stk. | D25: 2
A26: BB576367 | B26: R02R02G1 | C26: Spaltenanker (normal) | D26: ---
A27: BD300302 | B27: R02R02G1 | C27: Spaltenanker (für ungerade Spalten) | D27: ---
A28: LD110000 | B28: L1T53F02 | C28: Kreuzschellen (pro Sep.tor zwei Stück) | D28: 2
A29: L9113801894 | B29: L1T10F07 | C29: Druckluftdrossel für Selektionstor | D29: 2
A30: BB300840 | B30: *10 | C30: Kopfplattenhalter für Torwächter-Standpfosten | D30: 0
A31: L9106600203 | B31: L1T01F06 | C31: Schlauchschellen Milchleitung (16-25 mm) | D31: ---
A32: L9106600542 | B32: L1T03F08 | C32: Schlauchschellen Dippmittel (10,5-12 mm) | D32: ---
A33: RMHR8X1ES4A | B33: L1T58F01 | C33: Ansauglanze für Multi-Dos Flüssigdosierer | D33: ---
A34: RMHIQS100 | B34: L1T20F11 | C34: Rückschlagventile für Flüssigfütterung | D34: ---
A35: L5100417210 | B35: L1T05F13 | C35: Material 2.Austreiber(Kabel+Kappe+Plastikschraube) | D35: 1
A36: EE564850 | B36: L1T58F01 | C36: Vierkantrohr für zweiten Austreiber | D36: 1
A37: WÜ00581080 | B37: L1T02F09 | C37: Augenschraube (1x/Roboter) | D37: 1
A38: WÜ5176020003 | B38: R01R05B1 | C38: Edelstahlkette (2,5 mtr. / Roboter) | D38: 1
A39: L5100426410 | B39: R01R05B1 | C39: Klammer (1x / Roboter) | D39: 1
A40: L9114700125 | B40: L1T17F07 | C40: Karabiner (1x / Roboter) | D40: 1
...

Sheet Zusatz
A1: =Montage!A1 -> Roboterauslieferungsliste 01.26
A2: Kunde: | B2: =IF(Montage!B2=0,"",Montage!B2)
A3: Anschrift: | B3: =IF(Montage!B3=0,"",Montage!B3)
A4: =IF(Montage!A4=0,"",Montage!A4) -> LC Wernberg | B4: =IF(Montage!B4=0,"",Montage!B4)
A5: Kundennr: | B5: =IF(Montage!B5=0,"",Montage!B5)
A6: Projektnr: | B6: =IF(Montage!B6=0,"",Montage!B6) | D6: Telefon: | F6: =IF(Montage!F6=0,"",Montage!F6)
A7: Seriennr: | B7: =IF(Montage!B7=0,"",Montage!B7) | D7: Lieferdatum: | F7: =IF(Montage!F7=0,"",Montage!F7)
A8: Auftragsnr: | B8: =IF(Montage!B8=0,"",Montage!B8) | D8: Projektierer: | F8: =IF(Montage!F8=0,"",Montage!F8)
A9: Artikelnr.: | B9: Lagerort: | C9: Artikel: | D9: Stück | E9: Länge (m) | F9: Ausge liefert | G9: Nachlie ferung
A10: FE365912 | B10: Verbrauch | C10: Klebeband (grau)
A11: FE225081 | B11: L1T51F02 | C11: Platten für Gitterrinne (Pack. 25 Stk)
A12: FE225082 | B12: L1T51F02 | C12: Schrauben/Kepsmutter für Gitterr. Platten (Pack. 100 Stk)
A13: FE803592 | B13: WALA01 | C13: Tip-Rohr M 25 inkl. Schellen (3m)
A14: FE132129 | B14: R1R03C3 | C14: Steuerleitung: 2 x 1,0mm² (CRS-Kom.) (100m)
A15: FE132203 | B15: R01R03G1 | C15: Steuerleitung: 7 x 0,75mm² (CRS-Wedh. + Fremdtank) (100m)
A16: FE135472 | B16: R03R01D1 | C16: Steuerleitung: 3 x 1,5mm² (CRS-Fremdtank) (100m)
A17: FE025406 | B17: R02R04B1 | C17: Datenkabel CAT 7 (250m)
A18: FE050470 | B18: *10 | C18: Kabelkanal 110 (2m, Lichtgrau)
A19: L9118503515 | B19: R01R04D1 | C19: M4USE Schlauch (25m)
A20: L9113709372 | B20: L1T04F02 | C20: Milchleitungsschellen "schwarz" (10 Stk)
A21: L9106500646 | B21: R04R01C2 | C21: Milch-Schlauch Silikon (22 x 3,5) 25m
... A34: L5100417270 | B34: L1T05F11 | C34: Einschrauber für CU 19er Leitungen

Sheet Maschine
A1: =Montage!A1 -> Roboterauslieferungsliste 01.26
A2: Kunde: | B2: =IF(Montage!B2=0,"",Montage!B2)
A3: Anschrift: | B3: =IF(Montage!B3=0,"",Montage!B3)
A4: =IF(Montage!A4=0,"",Montage!A4) -> LC Wernberg | B4: =IF(Montage!B4=0,"",Montage!B4)
A5: Kundennr: | B5: =IF(Montage!B5=0,"",Montage!B5)
A6: Projektnr: | B6: =IF(Montage!B6=0,"",Montage!B6) | D6: Telefon: | E6: =IF(Montage!F6=0,"",Montage!F6)
A7: Seriennr: | B7: =IF(Montage!B7=0,"",Montage!B7) | D7: Lieferdatum: | E7: =IF(Montage!F7=0,"",Montage!F7)
A8: Auftragsnr: | B8: =IF(Montage!B8=0,"",Montage!B8) | D8: Projektierer: | E8: =IF(Montage!F8=0,"",Montage!F8)
A9: Artikelnr.: | B9: Lagerort: | C9: Artikel: | D9: Stück | E9: Ausge liefert | F9: Nachlie ferung
A10: 5.1005.0020-007 | B10: VK | C10: Astronaut A5 ( ) rechts, ( ) links
A11: 5.1005.3837.0 | B11: VK | C11: zusätzlicher Futterdosierer
A12: 5.1005.3645.0 | B12: VK | C12: Pura - Steam Cleaner
A13: 5.1004.2897.0 | B13: VK | C13: MQC-C type 3 + Bedienungsanleitung
A14: 5.1005.0030-002 | B14: VK | C14: Zentraleinheit, S/Nr:
A15: 5.1005.3740.0 | B15: VK | C15: Installations-Basispaket
A16: 5.1005.3741.0 | B16: VK | C16: Install.-Doppelp. (9.1190.0105.0 & 9.1190.0452.0)
A17: 5.1005.3244.0 | B17: VK | C17: Central uddercare pump mit Sauglanze und Sensor
A18: 5.1005.3261.0 | B18: VK | C18: GIOB Set
A19: 5.1004.1655.0 | B19: VK | C19: Gummimatte incl. Rost (Floor assembly)
A20: 5.1004.1100.0 | B20: VK | C20: M4USE
A21: 5.1005.6000.0 | B21: VK | C21: Milk for Use (+ Kabel 7,2m oder 15m)
... A49: SLDQ-LELY-5,5 | B49: VK | C49: Renner Kompressor 5,5 KW, Se.Nr.:
B50: VK | C50: Boetech Puffertank, Größe:
A51: L300550 | B51: VK | C51: Boetech Automatiktor 3 Meter
A52: L300551 | B52: VK | C52: Boetech Automatiktor 5 Meter
A53: L302580 | B53: VK | C53: Set Fernbedienung Automatiktor
B54: VK | C54: Tankmodell, S/Nr:
C55: ERSATZTEILE
A56: LD086269 | B56: *10 | C56: Schelle 47-51 mm (6/Collector)
A57: LD961775 | B57: *10 | C57: Schraube M8x120 mm (6/Collector)
C58: Rohr verzinkt ø 50mm, Länge 1,80m (1/Coll.)
A59: EE563282 | B59: R04R02B1 | C59: Gerade Streifen 1,50 m (Standard 6/Juno)
A60: EE561801 | B60: R04R02B1 | C60: Streifen Kurve (nur nach Angabe)
A61: H036473005 | B61: R01R03A3 | C61: Hanskamp Multi-Dos
A62: H001358000 | B62: R04R03B1 | C62: Hanskamp Pipefeeder
A63: H002677031 | B63: *10 | C63: Hanskamp Black-V Pulverdosierer kompl.
A64: L9.1187.0002.4 | B64: *10 | C64: Rohrkühler
A65: L36118700024 | B65: *10 | C65: Rohrkühler-Kit
A66: L9118501835 | B66: L1T50F02 | C66: Filterspenderbox
A67: L5.9723.0000.1 | B67: *10 | C67: Texastor komplett
...

Sheet HM
A1: =Montage!A1 -> Roboterauslieferungsliste 01.26
A2: Kunde: | B2: =IF(Montage!B2=0,"",Montage!B2)
A3: Anschrift: | B3: =IF(Montage!B3=0,"",Montage!B3)
A4: =IF(Montage!A4=0,"",Montage!A4) -> LC Wernberg | B4: =IF(Montage!B4=0,"",Montage!B4)
A5: Kundennr: | B5: =IF(Montage!B5=0,"",Montage!B5)
A6: Projektnr: | B6: =IF(Montage!B6=0,"",Montage!B6) | D6: Telefon: | E6: =IF(Montage!F6=0,"",Montage!F6)
A7: Seriennr: | B7: =IF(Montage!B7=0,"",Montage!B7) | D7: Lieferdatum: | E7: =IF(Montage!F7=0,"",Montage!F7)
A8: Auftragsnr: | B8: =IF(Montage!B8=0,"",Montage!B8) | D8: Projektierer: | E8: =IF(Montage!F8=0,"",Montage!F8)
A9: Artikelnr.: | B9: Lagerort: | C9: Artikel: | D9: Stück | E9: Ausge liefert | F9: Nachlie ferung
C10: Ersatzteile
A11: LD 75750 | B11: *10 | C11: Kanister Power Liquid Max (40 kg)
A12: L5970020700 | B12: R03R02D1 | C12: Änderung Zitzengummi in M23
A13: L5970022570 | B13: R03R01B1 | C13: Änderung Zitzengummi in M22
A14: L5970020730 | B14: R03R02B1 | C14: Änderung Zitzengummi in M21Soft
A15: L5970021070 | B15: *10 | C15: Verschleißteilpaket A4/A5
A16: LDTOOLBOX | C16: Werkzeugbox (Selbstzusammengestellte Box)
A17: BD300386 | B17: R02R04A1 | C17: Einmelkbügel " rechts "
A18: BD300385 | B18: R03R01A1 | C18: Einmelkbügel " links "
A19: L300400 | B19: *10 | C19: Standpfosten 2,5" x 1,5m
A20: L3004003 | B20: *10 | C20: Standpfosten 2,5" x 3m
A21: LD1007 | B21: R04R01B1 | C21: Rohrset gegen Aufspringen
A22: L5100460540 | B22: L1T36F02 | C22: Umbausatz Ketten (4Stk.)
A23: LD1004 | B23: L1T09F04 | C23: Ventil Handansetzen/ Vakkumentlastung
A24: BD201032 | B24: *10 | C24: Milchtaxianbindung - Dreiwegeventil
A25: LD086269 | B25: *10 | C25: - Schellen für Milchtaxianbindung
A26: LD961775 | B26: *10 | C26: - Stockschrauben für Milchtaxianb.
A27: L9106600656 | B27: L1T02F05 | C27: - Tri-Clamp klein
A28: L9113000283 | B28: L1T05F08 | C28: - Dichtung
C29: Puffertank - Montagematerial
A30: L5108007310 | B30: L1T04F09 | C30: - Anschluss Milchleitung Tri-Clamp 90° Bogen
A31: L9106600656 | B31: L1T02F05 | C31: - Tri-Clamp klein
A32: L9113000283 | B32: L1T05F08 | C32: - Dichtung
A33: L9106600203 | B33: L1T01F06 | C33: - Schlauchschellen Milchleitung (16-25 mm)
C34: Grazeway-Montagematerial
A35: FE180016 | B35: *10 | C35: Stromkabel 3x 1,5mm² Erdkabelausführung Flex
A36: FE842648 | B36: *10 | C36: Datenkabel CAT 7 Erdkabelausführung
A37: L9113801533 | B37: R02R02A2 | C37: Luftschlauch 10mm (50m)
A38: FE095930 | C38: FRAE flexibles Isolierrohr FBY-EL-F32 schwarz
A39: FE518915 | C39: FRAE Alu-Steckrohr Alu-Steck-E32
A40: FE459625 | C40: FRAE Alu-Steckbogen ABS-E 32
...

Sheet Reinigungsmittel
A1: =Montage!A1 -> Roboterauslieferungsliste 01.26
A2: Kunde: | B2: =IF(Montage!B2=0,"",Montage!B2)
A3: Anschrift: | B3: =IF(Montage!B3=0,"",Montage!B3)
A4: =IF(Montage!A4=0,"",Montage!A4) -> LC Wernberg | B4: =IF(Montage!B4=0,"",Montage!B4)
A5: Kundennummer: | B5: =IF(Montage!B5=0,"",Montage!B5)
A6: Projektnummer: | B6: =IF(Montage!B6=0,"",Montage!B6) | C6: Telefon: | D6: =IF(Montage!F6=0,"",Montage!F6)
A7: Seriennummer: | B7: =IF(Montage!B7=0,"",Montage!B7) | C7: Lieferdatum: | D7: =IF(Montage!F7=0,"",Montage!F7)
A8: Auftragsnummer: | B8: =IF(Montage!B8=0,"",Montage!B8) | C8: Projektierer: | D8: =IF(Montage!F8=0,"",Montage!F8)
A9: Artikelnr.: | B9: Artikel: | C9: Stück | D9: Ausge liefert | E9: Nachlie ferung
B10: ↓ Reinigungsmittel nur durch HM ausliefern - GEFAHRGUT ↓
A11: L5970021110 | B11: Kanister Astri- LC
A12: L5970021120 | B12: Kanister Astri- Lin
A13: L5970021130 | B13: Kanister Astri- Cid
C14: --- | D14: --- | E14: ---
A15: L5970022310 | B15: Kanister Reca Duo A, Tankreiniger "alkalisch"
A16: L5970022320 | B16: Kanister Reca Duo S, Tankreiniger "sauer"
B17: ↑ Reinigungsmittel nur durch HM ausliefern - GEFAHRGUT ↑
A18: L5970149170 | B18: Quaress-Fundo 60kg
C19: --- | D19: --- | E19: ---
A20: L5970022160 | B20: Astri-Cell Starter Kit
A21: L5970020460 | B21: Astri-Cell Konzentrat (1 Liter)
C22: --- | D22: --- | E22: ---
A23: L5970141090 | B23: Fl. Lely TDS Clean
A24: L5970022580 | B24: Essentials Vakuumpumpen-Reiniger
